Workbook
Name Slicer_JULY: #N/A
Name Slicer_MONTHLY_FEES: #N/A
Name Slicer_STANDARD: #N/A
Name Slicer_STATUS: #N/A

Sheet Home Page

Sheet Dashboard_1
B2: 📚 TUITION MANAGEMENT DASHBOARD ONE 2026 - 2027
B4: TOTAL STUDENTS ADMITTED | F4: ACTIVE STUDENTS | J4: LEFT STUDENTS | N4: TOTAL ANC
B5: =Dashboard_2!I19 -> 63 | F5: =Dashboard_2!G19 -> 58 | J5: =Dashboard_2!F19 -> 5 | N5: =Dashboard_2!H19 -> 0
B9: ACTIVE FEES | F9: YEARLY FEES | J9: MONTHLY FEES | N9: LEFT FEES
B10: =Dashboard_2!C13 -> 20250 | F10: =Dashboard_2!C14 -> 5900 | J10: =Dashboard_2!C15 -> 14350 | N10: =Dashboard_2!C7 -> 3050
B14: TOTAL PAID FEES | F14: TOTAL PENDING FEES | J14: CRNT MONTH PNDG FEES | N14: CRNT MONTH PAID FEES
B15: =Dashboard_2!M19 -> 16250 | F15: =Dashboard_2!Q19 -> 65300 | J15: =Dashboard_2!Q8-'Yearly Fees'!H13 -> 700 | N15: =Dashboard_2!M8 -> 12250

Sheet Dashboard_2
B2: 📚 TUITION MANAGEMENT DASHBOARD TWO 2026 - 2027
B4: TOTAL FEES | E4: ADMISSION DIVISION INTO LEFT / ACTIVE / ANC | K4: MONTH WISE PAID | O4: MONTH WISE PENDING
B6: TOTAL AMOUNT | C6: =SUM('All Names'!E8:E117) -> 23300 | E6: STANDARD | F6: LEFT | G6: ACTIVE | H6: ANC | I6: TOTAL | K6: MONTH | L6: TOTAL PAID FEES | M6: AMOUNT | O6: MONTH | P6: TOTAL PENDING FEES | Q6: AMOUNT
B7: TOTAL LEFT AMOUNT | C7: =SUMIF('All Names'!F8:F117,"LEFT ",'All Names'!E8:E117) -> 3050 | E7: 0TH | F7: =COUNTIFS('All Names'!C8:C117,"0th",'All Names'!F8:F117,"LEFT ") -> 1 | G7: =COUNTIFS('All Names'!C8:C117,"0th",'All Names'!F8:F117,"ACTIVE ") -> 8 | H7: =COUNTIFS('All Names'!C8:C117,"0th",'All Names'!F8:F117,"ANC") -> 0 | I7: =F7+G7+H7 -> 9 | K7: JUNE | L7: =COUNTIF('Regular Fees '!E7:E116,"PAID") -> 16 | M7: =SUMIF('Regular Fees '!E7:E116,"PAID",'Regular Fees '!D7:D116) -> 4000 | O7: JUNE | P7: =COUNTIF('Regular Fees '!E7:E116,"UNPAID") -> 11 | Q7: =SUMIF('Regular Fees '!E7:E116,"UNPAID",'Regular Fees '!D7:D116) -> 5600
B8: TOTAL ANC AMOUNT | C8: =SUMIF('All Names'!F8:F117,"ANC",'All Names'!E8:E117) -> 0 | E8: JR.KG/SR.KG | F8: =COUNTIFS('All Names'!C8:C117,"Jr.kg/Sr.kg",'All Names'!F8:F117,"LEFT ") -> 0 | G8: =COUNTIFS('All Names'!C8:C117,"Jr.kg/Sr.kg",'All Names'!F8:F117,"ACTIVE ") -> 6 | H8: =COUNTIFS('All Names'!C8:C117,"Jr.kg/Sr.kg",'All Names'!F8:F117,"ANC") -> 0 | I8: =F8+G8+H8 -> 6 | K8: JULY | L8: =COUNTIF('Regular Fees '!F7:F117,"PAID") -> 36 | M8: =SUMIF('Regular Fees '!F7:F116,"PAID",'Regular Fees '!D7:D116) -> 12250 | O8: JULY | P8: =COUNTIF('Regular Fees '!F7:F116,"UNPAID") -> 15 | Q8: =SUMIF('Regular Fees '!F7:F116,"UNPAID",'Regular Fees '!D7:D116) -> 6600
B9: TOTAL ACTIVE AMOUNT | C9: =C6-C7-C8 -> 20250 | E9: 1ST | F9: =COUNTIFS('All Names'!C8:C117,"1st",'All Names'!F8:F117,"LEFT ") -> 0 | G9: =COUNTIFS('All Names'!C8:C117,"1st",'All Names'!F8:F117,"ACTIVE ") -> 7 | H9: =COUNTIFS('All Names'!C8:C117,"1st",'All Names'!F8:F117,"ANC") -> 0 | I9: =F9+G9+H9 -> 7 | K9: AUGUST | L9: =COUNTIF('Regular Fees '!G7:G117,"PAID") -> 3 | M9: =SUMIF('Regular Fees '!G7:G116,"PAID",'Regular Fees '!D7:D116) -> 0 | O9: AUGUST | P9: =COUNTIF('Regular Fees '!G7:G116,"UNPAID") -> 12 | Q9: =SUMIF('Regular Fees '!G7:G116,"UNPAID",'Regular Fees '!D7:D116) -> 5900
E10: 2ND | F10: =COUNTIFS('All Names'!C8:C117,"2nd",'All Names'!F8:F117,"LEFT ") -> 1 | G10: =COUNTIFS('All Names'!C8:C117,"2nd",'All Names'!F8:F117,"ACTIVE ") -> 4 | H10: =COUNTIFS('All Names'!C8:C117,"2nd",'All Names'!F8:F117,"ANC") -> 0 | I10: =F10+G10+H10 -> 5 | K10: SEPTEMBER | L10: =COUNTIF('Regular Fees '!H7:H117,"PAID") -> 3 | M10: =SUMIF('Regular Fees '!H7:H116,"PAID",'Regular Fees '!D7:D116) -> 0 | O10: SEPTEMBER | P10: =COUNTIF('Regular Fees '!H7:H116,"UNPAID") -> 12 | Q10: =SUMIF('Regular Fees '!H7:H116,"UNPAID",'Regular Fees '!D7:D116) -> 5900
B11: ACTIVE/YEARLY/MONTLY FEES | E11: 3RD | F11: =COUNTIFS('All Names'!C8:C117,"3rd",'All Names'!F8:F117,"LEFT ") -> 0 | G11: =COUNTIFS('All Names'!C8:C117,"3rd",'All Names'!F8:F117,"ACTIVE ") -> 9 | H11: =COUNTIFS('All Names'!C8:C117,"3rd",'All Names'!F8:F117,"ANC") -> 0 | I11: =F11+G11+H11 -> 9 | K11: OCTOBER | L11: =COUNTIF('Regular Fees '!I7:I117,"PAID") -> 3 | M11: =SUMIF('Regular Fees '!I7:I116,"PAID",'Regular Fees '!D7:D116) -> 0 | O11: OCTOBER | P11: =COUNTIF('Regular Fees '!I7:I116,"UNPAID") -> 12 | Q11: =SUMIF('Regular Fees '!I7:I116,"UNPAID",'Regular Fees '!D7:D116) -> 5900
E12: 4TH | F12: =COUNTIFS('All Names'!C8:C117,"4th",'All Names'!F8:F117,"LEFT ") -> 0 | G12: =COUNTIFS('All Names'!C8:C117,"4th",'All Names'!F8:F117,"ACTIVE ") -> 11 | H12: =COUNTIFS('All Names'!C8:C117,"4th",'All Names'!F8:F117,"ANC") -> 0 | I12: =F12+G12+H12 -> 11 | K12: NOVEMBER | L12: =COUNTIF('Regular Fees '!J7:J117,"PAID") -> 3 | M12: =SUMIF('Regular Fees '!J7:J116,"PAID",'Regular Fees '!D7:D116) -> 0 | O12: NOVEMBER | P12: =COUNTIF('Regular Fees '!J7:J116,"UNPAID") -> 12 | Q12: =SUMIF('Regular Fees '!J7:J116,"UNPAID",'Regular Fees '!D7:D116) -> 5900
B13: ACTIVE FEES | C13: =Dashboard_2!C9 -> 20250 | E13: 5TH | F13: =COUNTIFS('All Names'!C8:C117,"5th",'All Names'!F8:F117,"LEFT ") -> 1 | G13: =COUNTIFS('All Names'!C8:C117,"5th",'All Names'!F8:F117,"ACTIVE ") -> 6 | H13: =COUNTIFS('All Names'!C8:C117,"5th",'All Names'!F8:F117,"ANC") -> 0 | I13: =F13+G13+H13 -> 7 | K13: DECEMBER | L13: =COUNTIF('Regular Fees '!K7:K117,"PAID") -> 3 | M13: =SUMIF('Regular Fees '!K7:K116,"PAID",'Regular Fees '!D7:D116) -> 0 | O13: DECEMBER | P13: =COUNTIF('Regular Fees '!K7:K116,"UNPAID") -> 12 | Q13: =SUMIF('Regular Fees '!K7:K116,"UNPAID",'Regular Fees '!D7:D116) -> 5900
B14: YEARLY FEES | C14: =SUM('Yearly Fees'!H7:H12) -> 5900 | E14: 6TH | F14: =COUNTIFS('All Names'!C8:C117,"6th",'All Names'!F8:F117,"LEFT ") -> 0 | G14: =COUNTIFS('All Names'!C8:C117,"6th",'All Names'!F8:F117,"ACTIVE ") -> 2 | H14: =COUNTIFS('All Names'!C8:C117,"6th",'All Names'!F8:F117,"ANC") -> 0 | I14: =F14+G14+H14 -> 2 | K14: JANUARY | L14: =COUNTIF('Regular Fees '!L7:L117,"PAID") -> 3 | M14: =SUMIF('Regular Fees '!L7:L116,"PAID",'Regular Fees '!D7:D116) -> 0 | O14: JANUARY | P14: =COUNTIF('Regular Fees '!L7:L116,"UNPAID") -> 12 | Q14: =SUMIF('Regular Fees '!L7:L116,"UNPAID",'Regular Fees '!D7:D116) -> 5900
B15: MONTLY FEES | C15: =C13-C14 -> 14350 | E15: 7TH | F15: =COUNTIFS('All Names'!C8:C117,"7th",'All Names'!F8:F117,"LEFT ") -> 0 | G15: =COUNTIFS('All Names'!C8:C117,"7th",'All Names'!F8:F117,"ACTIVE ") -> 0 | H15: =COUNTIFS('All Names'!C8:C117,"7th",'All Names'!F8:F117,"ANC") -> 0 | I15: =F15+G15+H15 -> 0 | K15: FEBRUARY | L15: =COUNTIF('Regular Fees '!M7:M117,"PAID") -> 3 | M15: =SUMIF('Regular Fees '!M7:M116,"PAID",'Regular Fees '!D7:D116) -> 0 | O15: FEBRUARY | P15: =COUNTIF('Regular Fees '!M7:M116,"UNPAID") -> 12 | Q15: =SUMIF('Regular Fees '!M7:M116,"UNPAID",'Regular Fees '!D7:D116) -> 5900
E16: 8TH | F16: =COUNTIFS('All Names'!C8:C117,"8th",'All Names'!F8:F117,"LEFT ") -> 1 | G16: =COUNTIFS('All Names'!C8:C117,"8th",'All Names'!F8:F117,"ACTIVE ") -> 2 | H16: =COUNTIFS('All Names'!C8:C117,"8th",'All Names'!F8:F117,"ANC") -> 0 | I16: =F16+G16+H16 -> 3 | K16: MARCH | L16: =COUNTIF('Regular Fees '!N7:N117,"PAID") -> 3 | M16: =SUMIF('Regular Fees '!N7:N116,"PAID",'Regular Fees '!D7:D116) -> 0 | O16: MARCH | P16: =COUNTIF('Regular Fees '!N7:N116,"UNPAID") -> 12 | Q16: =SUMIF('Regular Fees '!N7:N116,"UNPAID",'Regular Fees '!D7:D116) -> 5900
B17: FEES CHECKER | E17: 9TH | F17: =COUNTIFS('All Names'!C8:C117,"9th",'All Names'!F8:F117,"LEFT ") -> 0 | G17: =COUNTIFS('All Names'!C8:C117,"9th",'All Names'!F8:F117,"ACTIVE ") -> 2 | H17: =COUNTIFS('All Names'!C8:C117,"9th",'All Names'!F8:F117,"ANC") -> 0 | I17: =F17+G17+H17 -> 2 | K17: APRIL | L17: =COUNTIF('Regular Fees '!O7:O117,"PAID") -> 3 | M17: =SUMIF('Regular Fees '!O7:O116,"PAID",'Regular Fees '!D7:D116) -> 0 | O17: APRIL | P17: =COUNTIF('Regular Fees '!O7:O116,"UNPAID") -> 12 | Q17: =SUMIF('Regular Fees '!O7:O116,"UNPAID",'Regular Fees '!D7:D116) -> 5900
E18: 10TH | F18: =COUNTIFS('All Names'!C8:C117,"10th",'All Names'!F8:F117,"LEFT ") -> 1 | G18: =COUNTIFS('All Names'!C8:C117,"10th",'All Names'!F8:F117,"ACTIVE ") -> 1 | H18: =COUNTIFS('All Names'!C8:C117,"10th",'All Names'!F8:F117,"ANC") -> 0 | I18: =F18+G18+H18 -> 2 | K18: MAY | L18: =COUNTIF('Regular Fees '!P7:P117,"PAID") -> 0 | M18: =SUMIF('Regular Fees '!P7:P116,"PAID",'Regular Fees '!D7:D116) -> 0 | O18: MAY | P18: =COUNTIF('Regular Fees '!P7:P116,"UNPAID") -> 0 | Q18: =SUMIF('Regular Fees '!P7:P116,"UNPAID",'Regular Fees '!D7:D116) -> 0
B19: STUDENT NAME | C19: FEES | E19: TOTAL | F19: =SUM(F7:F18) -> 5 | G19: =SUM(G7:G18) -> 58 | H19: =SUM(H7:H18) -> 0 | I19: =SUM(I7:I18) -> 63 | K19: TOTAL PAID | M19: =SUM(M7:M18) -> 16250 | O19: TOTAL PENDING | Q19: =SUM(Q7:Q18) -> 65300
B20: Student 5 | C20: =VLOOKUP(Dashboard_2!B20,Table6[[NAME]:[FEES AMOUNT]],3,FALSE) -> 800
B23: STUDENT NAME | C23: FEES MONTH
B24: Student 3 | C24: OCTOBER
B26: =INDEX('Regular Fees '!E7:P116,MATCH(B24,'Regular Fees '!B7:B116,0),MATCH(C24,Table6[[#Headers],[JUNE]:[MAY]],0)) -> UNPAID
B30: SHORT FORM / FULL FORM
B32: FULL FORM | C32: SHORT FORM
B33: TOTAL MONTH FEES PAID | C33: TMFP
B34: TOTAL PAID FEES AMOUNT | C34: TPFA
B35: TOTAL MONTH UNPAID FEES | C35: TMUPF
B36: TOTAL UNPAID FEES AMOUNT | C36: TUPFA
B37: ADMITTED NOT COMING | C37: ANC
B38: MORNING | C38: MOR
B39: EVENING | C39: EVE
B40: PENDING FEES EXCLUDING YEARLY FEES | C40: PFEYF

Sheet Dashboard_3
B2: 📚 TUITION MANAGEMENT DASHBOARD THREE 2026 - 2027

Sheet Graph Visualization
A1: GRAPH VISUALIZATION : 2026 - 2027

Sheet All Names
A2: 📚 ALL STUDENTS ADMISSION DETAIL : 2026 - 2027
A7: SR. NO. | B7: STUDENT NAME | C7: STANDARD | D7: CONTACT | E7: MONTHLY FEES | F7: STATUS | G7: ADMISSION DATE | H7: LEAVE DATE | I7: MOR/EVE
A8: =ROW()-7 -> 1 | B8: ="Student "&(ROW()-7) -> Student 1 | C8: 0th | D8: - | E8: 200 | F8: ACTIVE | G8: 46174 | H8: - | I8: MORNING
A9: =ROW()-7 -> 2 | B9: ="Student "&(ROW()-7) -> Student 2 | C9: 4th | D9: - | E9: 400 | F9: ACTIVE | G9: 46174 | H9: - | I9: MORNING
A10: =ROW()-7 -> 3 | B10: ="Student "&(ROW()-7) -> Student 3 | C10: 1st | D10: - | E10: 400 | F10: ACTIVE | G10: 46174 | H10: - | I10: MORNING
A11: =ROW()-7 -> 4 | B11: ="Student "&(ROW()-7) -> Student 4 | C11: 0th | D11: - | E11: 0 | F11: ACTIVE | G11: 46174 | H11: - | I11: MORNING
A12: =ROW()-7 -> 5 | B12: ="Student "&(ROW()-7) -> Student 5 | C12: 8th | D12: - | E12: 800 | F12: ACTIVE | G12: 46174 | H12: - | I12: EVENING
A13: =ROW()-7 -> 6 | B13: ="Student "&(ROW()-7) -> Student 6 | C13: 9th | D13: - | E13: 900 | F13: ACTIVE | G13: 46174 | H13: - | I13: EVENING
A14: =ROW()-7 -> 7 | B14: ="Student "&(ROW()-7) -> Student 7 | C14: 6th | D14: - | E14: 600 | F14: ACTIVE | G14: 46174 | H14: - | I14: EVENING
A15: =ROW()-7 -> 8 | B15: ="Student "&(ROW()-7) -> Student 8 | C15: 1st | D15: - | E15: 250 | F15: ACTIVE | G15: 46174 | H15: - | I15: MORNING
A16: =ROW()-7 -> 9 | B16: ="Student "&(ROW()-7) -> Student 9 | C16: 0th | D16: - | E16: 0 | F16: ACTIVE | G16: 46174 | H16: - | I16: MORNING
A17: =ROW()-7 -> 10 | B17: ="Student "&(ROW()-7) -> Student 10 | C17: 10th | D17: - | E17: 1300 | F17: LEFT | G17: 46174 | H17: 46193 | I17: EVENING
A18: =ROW()-7 -> 11 | B18: ="Student "&(ROW()-7) -> Student 11 | C18: 8th | D18: - | E18: 800 | F18: ACTIVE | G18: 46202 | H18: - | I18: EVENING
A19: =ROW()-7 -> 12 | B19: ="Student "&(ROW()-7) -> Student 12 | C19: 5th | D19: - | E19: 500 | F19: ACTIVE | G19: 46202 | H19: - | I19: EVENING
A20: =ROW()-7 -> 13 | B20: ="Student "&(ROW()-7) -> Student 13 | C20: 1st | D20: - | E20: 200 | F20: ACTIVE | G20: 46174 | H20: - | I20: MORNING
A21: =ROW()-7 -> 14 | B21: ="Student "&(ROW()-7) -> Student 14 | C21: 4th | D21: - | E21: 400 | F21: ACTIVE | G21: 46174 | H21: - | I21: MORNING
A22: =ROW()-7 -> 15 | B22: ="Student "&(ROW()-7) -> Student 15 | C22: 3rd | D22: - | E22: 300 | F22: ACTIVE | G22: 46174 | H22: - | I22: MORNING
A23: =ROW()-7 -> 16 | B23: ="Student "&(ROW()-7) -> Student 16 | C23: 10th | D23: - | E23: 1200 | F23: ACTIVE | G23: 46113 | H23: - | I23: EVENING
A24: =ROW()-7 -> 17 | B24: ="Student "&(ROW()-7) -> Student 17 | C24: 3rd | D24: - | E24: 300 | F24: ACTIVE | G24: 46192 | H24: - | I24: MORNING
A25: =ROW()-7 -> 18 | B25: ="Student "&(ROW()-7) -> Student 18 | C25: 4th | D25: - | E25: 350 | F25: ACTIVE | G25: 46192 | H25: - | I25: MORNING
A26: =ROW()-7 -> 19 | B26: ="Student "&(ROW()-7) -> Student 19 | C26: 1st | D26: - | E26: 250 | F26: ACTIVE | G26: 46175 | H26: - | I26: MORNING
A27: =ROW()-7 -> 20 | B27: ="Student "&(ROW()-7) -> Student 20 | C27: 4th | D27: - | E27: 300 | F27: ACTIVE | G27: 46175 | H27: - | I27: MORNING
A28: =ROW()-7 -> 21 | B28: ="Student "&(ROW()-7) -> Student 21 | C28: 5th | D28: - | E28: 500 | F28: LEFT | G28: 46175 | H28: 46178 | I28: EVENING
A29: =ROW()-7 -> 22 | B29: ="Student "&(ROW()-7) -> Student 22 | C29: 2nd | D29: - | E29: 250 | F29: LEFT | G29: 46175 | H29: 46244 | I29: MORNING
A30: =ROW()-7 -> 23 | B30: ="Student "&(ROW()-7) -> Student 23 | C30: 2nd | D30: - | E30: 250 | F30: ACTIVE | G30: 46176 | H30: - | I30: MORNING
A31: =ROW()-7 -> 24 | B31: ="Student "&(ROW()-7) -> Student 24 | C31: Jr.kg/Sr.kg | D31: - | E31: 200 | F31: ACTIVE | G31: 46176 | H31: - | I31: EVENING
A32: =ROW()-7 -> 25 | B32: ="Student "&(ROW()-7) -> Student 25 | C32: 5th | D32: - | E32: 500 | F32: ACTIVE | G32: 46182 | H32: - | I32: EVENING
A33: =ROW()-7 -> 26 | B33: ="Student "&(ROW()-7) -> Student 26 | C33: Jr.kg/Sr.kg | D33: - | E33: 0 | F33: ACTIVE | G33: 46182 | H33: - | I33: EVENING
A34: =ROW()-7 -> 27 | B34: ="Student "&(ROW()-7) -> Student 27 | C34: 3rd | D34: - | E34: 300 | F34: ACTIVE | G34: 46183 | H34: - | I34: EVENING
A35: =ROW()-7 -> 28 | B35: ="Student "&(ROW()-7) -> Student 28 | C35: 4th | D35: - | E35: 350 | F35: ACTIVE | G35: 46202 | H35: - | I35: MORNING
A36: =ROW()-7 -> 29 | B36: ="Student "&(ROW()-7) -> Student 29 | C36: Jr.kg/Sr.kg | D36: - | E36: 200 | F36: ACTIVE | G36: 46202 | H36: - | I36: EVENING
A37: =ROW()-7 -> 30 | B37: ="Student "&(ROW()-7) -> Student 30 | C37: 0th | D37: - | E37: 200 | F37: LEFT | G37: 46174 | H37: 46223 | I37: EVENING
A38: =ROW()-7 -> 31 | B38: ="Student "&(ROW()-7) -> Student 31 | C38: 3rd | D38: - | E38: 300 | F38: ACTIVE | G38: 46185 | H38: - | I38: EVENING
A39: =ROW()-7 -> 32 | B39: ="Student "&(ROW()-7) -> Student 32 | C39: Jr.kg/Sr.kg | D39: - | E39: 150 | F39: ACTIVE | G39: 46185 | H39: - | I39: EVENING
A40: =ROW()-7 -> 33 | B40: ="Student "&(ROW()-7) -> Student 33 | C40: 0th | D40: - | E40: 200 | F40: ACTIVE | G40: 46185 | H40: - | I40: MORNING
A41: =ROW()-7 -> 34 | B41: ="Student "&(ROW()-7) -> Student 34 | C41: 0th | D41: - | E41: 150 | F41: ACTIVE | G41: 46174 | H41: - | I41: MORNING
A42: =ROW()-7 -> 35 | B42: ="Student "&(ROW()-7) -> Student 35 | C42: 9th | D42: - | E42: 900 | F42: ACTIVE | G42: 46188 | H42: - | I42: EVENING
A43: =ROW()-7 -> 36 | B43: ="Student "&(ROW()-7) -> Student 36 | C43: 3rd | D43: - | E43: 250 | F43: ACTIVE | G43: 46195 | H43: - | I43: EVENING
A44: =ROW()-7 -> 37 | B44: ="Student "&(ROW()-7) -> Student 37 | C44: 1st | D44: - | E44: 200 | F44: ACTIVE | G44: 46195 | H44: - | I44: EVENING
A45: =ROW()-7 -> 38 | B45: ="Student "&(ROW()-7) -> Student 38 | C45: 3rd | D45: - | E45: 250 | F45: ACTIVE | G45: 46196 | H45: - | I45: MORNING
...

Sheet Regular Fees 
A1: FEES DETAILS : 2026 - 2027
A6: SR.NO. | B6: NAME | C6: STD | D6: FEES AMOUNT | E6: JUNE | F6: JULY | G6: AUGUST | H6: SEPTEMBER | I6: OCTOBER | J6: NOVEMBER | K6: DECEMBER | L6: JANUARY | M6: FEBRUARY | N6: MARCH | O6: APRIL | P6: MAY | Q6: TMFP | R6: TPFA | S6: TMUPF | T6: TUPFA
A7: =ROW()-6 -> 1 | B7: ='All Names'!B8 -> Student 1 | C7: ='All Names'!C8 -> 0th | D7: ='All Names'!E8 -> 200 | E7: PAID | F7: PAID | Q7: =COUNTIF(E7:P7,"PAID") -> 2 | R7: =D7*Q7 -> 400 | S7: =COUNTIF(E7:P7,"UNPAID") -> 0 | T7: =D7*S7 -> 0
A8: =ROW()-6 -> 2 | B8: ='All Names'!B9 -> Student 2 | C8: ='All Names'!C9 -> 4th | D8: ='All Names'!E9 -> 400 | E8: UNPAID | F8: UNPAID | G8: UNPAID | H8: UNPAID | I8: UNPAID | J8: UNPAID | K8: UNPAID | L8: UNPAID | M8: UNPAID | N8: UNPAID | O8: UNPAID | Q8: =COUNTIF(E8:P8,"PAID") -> 0 | R8: =D8*Q8 -> 0 | S8: =COUNTIF(E8:P8,"UNPAID") -> 11 | T8: =D8*S8 -> 4400
A9: =ROW()-6 -> 3 | B9: ='All Names'!B10 -> Student 3 | C9: ='All Names'!C10 -> 1st | D9: ='All Names'!E10 -> 400 | E9: UNPAID | F9: UNPAID | G9: UNPAID | H9: UNPAID | I9: UNPAID | J9: UNPAID | K9: UNPAID | L9: UNPAID | M9: UNPAID | N9: UNPAID | O9: UNPAID | Q9: =COUNTIF(E9:P9,"PAID") -> 0 | R9: =D9*Q9 -> 0 | S9: =COUNTIF(E9:P9,"UNPAID") -> 11 | T9: =D9*S9 -> 4400
A10: =ROW()-6 -> 4 | B10: ='All Names'!B11 -> Student 4 | C10: ='All Names'!C11 -> 0th | D10: ='All Names'!E11 -> 0 | E10: PAID | F10: PAID | G10: PAID | H10: PAID | I10: PAID | J10: PAID | K10: PAID | L10: PAID | M10: PAID | N10: PAID | O10: PAID | Q10: =COUNTIF(E10:P10,"PAID") -> 11 | R10: =D10*Q10 -> 0 | S10: =COUNTIF(E10:P10,"UNPAID") -> 0 | T10: =D10*S10 -> 0
A11: =ROW()-6 -> 5 | B11: ='All Names'!B12 -> Student 5 | C11: ='All Names'!C12 -> 8th | D11: ='All Names'!E12 -> 800 | E11: UNPAID | F11: UNPAID | G11: UNPAID | H11: UNPAID | I11: UNPAID | J11: UNPAID | K11: UNPAID | L11: UNPAID | M11: UNPAID | N11: UNPAID | O11: UNPAID | Q11: =COUNTIF(E11:P11,"PAID") -> 0 | R11: =D11*Q11 -> 0 | S11: =COUNTIF(E11:P11,"UNPAID") -> 11 | T11: =D11*S11 -> 8800
A12: =ROW()-6 -> 6 | B12: ='All Names'!B13 -> Student 6 | C12: ='All Names'!C13 -> 9th | D12: ='All Names'!E13 -> 900 | E12: UNPAID | F12: UNPAID | G12: UNPAID | H12: UNPAID | I12: UNPAID | J12: UNPAID | K12: UNPAID | L12: UNPAID | M12: UNPAID | N12: UNPAID | O12: UNPAID | Q12: =COUNTIF(E12:P12,"PAID") -> 0 | R12: =D12*Q12 -> 0 | S12: =COUNTIF(E12:P12,"UNPAID") -> 11 | T12: =D12*S12 -> 9900
A13: =ROW()-6 -> 7 | B13: ='All Names'!B14 -> Student 7 | C13: ='All Names'!C14 -> 6th | D13: ='All Names'!E14 -> 600 | E13: UNPAID | F13: UNPAID | G13: UNPAID | H13: UNPAID | I13: UNPAID | J13: UNPAID | K13: UNPAID | L13: UNPAID | M13: UNPAID | N13: UNPAID | O13: UNPAID | Q13: =COUNTIF(E13:P13,"PAID") -> 0 | R13: =D13*Q13 -> 0 | S13: =COUNTIF(E13:P13,"UNPAID") -> 11 | T13: =D13*S13 -> 6600
A14: =ROW()-6 -> 8 | B14: ='All Names'!B15 -> Student 8 | C14: ='All Names'!C15 -> 1st | D14: ='All Names'!E15 -> 250 | E14: UNPAID | F14: UNPAID | G14: UNPAID | H14: UNPAID | I14: UNPAID | J14: UNPAID | K14: UNPAID | L14: UNPAID | M14: UNPAID | N14: UNPAID | O14: UNPAID | Q14: =COUNTIF(E14:P14,"PAID") -> 0 | R14: =D14*Q14 -> 0 | S14: =COUNTIF(E14:P14,"UNPAID") -> 11 | T14: =D14*S14 -> 2750
A15: =ROW()-6 -> 9 | B15: ='All Names'!B16 -> Student 9 | C15: ='All Names'!C16 -> 0th | D15: ='All Names'!E16 -> 0 | E15: PAID | F15: PAID | G15: PAID | H15: PAID | I15: PAID | J15: PAID | K15: PAID | L15: PAID | M15: PAID | N15: PAID | O15: PAID | Q15: =COUNTIF(E15:P15,"PAID") -> 11 | R15: =D15*Q15 -> 0 | S15: =COUNTIF(E15:P15,"UNPAID") -> 0 | T15: =D15*S15 -> 0
A16: =ROW()-6 -> 10 | B16: ='All Names'!B17 -> Student 10 | C16: ='All Names'!C17 -> 10th | D16: ='All Names'!E17 -> 1300 | E16: LEFT | F16: LEFT | G16: LEFT | H16: LEFT | I16: LEFT | J16: LEFT | K16: LEFT | L16: LEFT | M16: LEFT | N16: LEFT | O16: LEFT | Q16: =COUNTIF(E16:P16,"PAID") -> 0 | R16: =D16*Q16 -> 0 | S16: =COUNTIF(E16:P16,"UNPAID") -> 0 | T16: =D16*S16 -> 0
A17: =ROW()-6 -> 11 | B17: ='All Names'!B18 -> Student 11 | C17: ='All Names'!C18 -> 8th | D17: ='All Names'!E18 -> 800 | E17: NOT CAME | F17: PAID | Q17: =COUNTIF(E17:P17,"PAID") -> 1 | R17: =D17*Q17 -> 800 | S17: =COUNTIF(E17:P17,"UNPAID") -> 0 | T17: =D17*S17 -> 0
A18: =ROW()-6 -> 12 | B18: ='All Names'!B19 -> Student 12 | C18: ='All Names'!C19 -> 5th | D18: ='All Names'!E19 -> 500 | E18: NOT CAME | F18: PAID | Q18: =COUNTIF(E18:P18,"PAID") -> 1 | R18: =D18*Q18 -> 500 | S18: =COUNTIF(E18:P18,"UNPAID") -> 0 | T18: =D18*S18 -> 0
A19: =ROW()-6 -> 13 | B19: ='All Names'!B20 -> Student 13 | C19: ='All Names'!C20 -> 1st | D19: ='All Names'!E20 -> 200 | E19: UNPAID | F19: UNPAID | G19: UNPAID | H19: UNPAID | I19: UNPAID | J19: UNPAID | K19: UNPAID | L19: UNPAID | M19: UNPAID | N19: UNPAID | O19: UNPAID | Q19: =COUNTIF(E19:P19,"PAID") -> 0 | R19: =D19*Q19 -> 0 | S19: =COUNTIF(E19:P19,"UNPAID") -> 11 | T19: =D19*S19 -> 2200
A20: =ROW()-6 -> 14 | B20: ='All Names'!B21 -> Student 14 | C20: ='All Names'!C21 -> 4th | D20: ='All Names'!E21 -> 400 | E20: PAID | F20: PAID | Q20: =COUNTIF(E20:P20,"PAID") -> 2 | R20: =D20*Q20 -> 800 | S20: =COUNTIF(E20:P20,"UNPAID") -> 0 | T20: =D20*S20 -> 0
A21: =ROW()-6 -> 15 | B21: ='All Names'!B22 -> Student 15 | C21: ='All Names'!C22 -> 3rd | D21: ='All Names'!E22 -> 300 | E21: PAID | F21: PAID | Q21: =COUNTIF(E21:P21,"PAID") -> 2 | R21: =D21*Q21 -> 600 | S21: =COUNTIF(E21:P21,"UNPAID") -> 0 | T21: =D21*S21 -> 0
A22: =ROW()-6 -> 16 | B22: ='All Names'!B23 -> Student 16 | C22: ='All Names'!C23 -> 10th | D22: ='All Names'!E23 -> 1200 | E22: UNPAID | F22: UNPAID | G22: UNPAID | H22: UNPAID | I22: UNPAID | J22: UNPAID | K22: UNPAID | L22: UNPAID | M22: UNPAID | N22: UNPAID | O22: UNPAID | Q22: =COUNTIF(E22:P22,"PAID") -> 0 | R22: =D22*Q22 -> 0 | S22: =COUNTIF(E22:P22,"UNPAID") -> 11 | T22: =D22*S22 -> 13200
A23: =ROW()-6 -> 17 | B23: ='All Names'!B24 -> Student 17 | C23: ='All Names'!C24 -> 3rd | D23: ='All Names'!E24 -> 300 | E23: NOT CAME | F23: PAID | Q23: =COUNTIF(E23:P23,"PAID") -> 1 | R23: =D23*Q23 -> 300 | S23: =COUNTIF(E23:P23,"UNPAID") -> 0 | T23: =D23*S23 -> 0
A24: =ROW()-6 -> 18 | B24: ='All Names'!B25 -> Student 18 | C24: ='All Names'!C25 -> 4th | D24: ='All Names'!E25 -> 350 | E24: NOT CAME | F24: PAID | Q24: =COUNTIF(E24:P24,"PAID") -> 1 | R24: =D24*Q24 -> 350 | S24: =COUNTIF(E24:P24,"UNPAID") -> 0 | T24: =D24*S24 -> 0
A25: =ROW()-6 -> 19 | B25: ='All Names'!B26 -> Student 19 | C25: ='All Names'!C26 -> 1st | D25: ='All Names'!E26 -> 250 | E25: PAID | F25: PAID | Q25: =COUNTIF(E25:P25,"PAID") -> 2 | R25: =D25*Q25 -> 500 | S25: =COUNTIF(E25:P25,"UNPAID") -> 0 | T25: =D25*S25 -> 0
A26: =ROW()-6 -> 20 | B26: ='All Names'!B27 -> Student 20 | C26: ='All Names'!C27 -> 4th | D26: ='All Names'!E27 -> 300 | E26: PAID | F26: PAID | Q26: =COUNTIF(E26:P26,"PAID") -> 2 | R26: =D26*Q26 -> 600 | S26: =COUNTIF(E26:P26,"UNPAID") -> 0 | T26: =D26*S26 -> 0
A27: =ROW()-6 -> 21 | B27: ='All Names'!B28 -> Student 21 | C27: ='All Names'!C28 -> 5th | D27: ='All Names'!E28 -> 500 | E27: LEFT | F27: LEFT | G27: LEFT | H27: LEFT | I27: LEFT | J27: LEFT | K27: LEFT | L27: LEFT | M27: LEFT | N27: LEFT | O27: LEFT | Q27: =COUNTIF(E27:P27,"PAID") -> 0 | R27: =D27*Q27 -> 0 | S27: =COUNTIF(E27:P27,"UNPAID") -> 0 | T27: =D27*S27 -> 0
A28: =ROW()-6 -> 22 | B28: ='All Names'!B29 -> Student 22 | C28: ='All Names'!C29 -> 2nd | D28: ='All Names'!E29 -> 250 | E28: PAID | F28: UNPAID | G28: LEFT | H28: LEFT | I28: LEFT | J28: LEFT | K28: LEFT | L28: LEFT | M28: LEFT | N28: LEFT | O28: LEFT | Q28: =COUNTIF(E28:P28,"PAID") -> 1 | R28: =D28*Q28 -> 250 | S28: =COUNTIF(E28:P28,"UNPAID") -> 1 | T28: =D28*S28 -> 250
A29: =ROW()-6 -> 23 | B29: ='All Names'!B30 -> Student 23 | C29: ='All Names'!C30 -> 2nd | D29: ='All Names'!E30 -> 250 | E29: PAID | F29: PAID | Q29: =COUNTIF(E29:P29,"PAID") -> 2 | R29: =D29*Q29 -> 500 | S29: =COUNTIF(E29:P29,"UNPAID") -> 0 | T29: =D29*S29 -> 0
A30: =ROW()-6 -> 24 | B30: ='All Names'!B31 -> Student 24 | C30: ='All Names'!C31 -> Jr.kg/Sr.kg | D30: ='All Names'!E31 -> 200 | E30: PAID | F30: PAID | Q30: =COUNTIF(E30:P30,"PAID") -> 2 | R30: =D30*Q30 -> 400 | S30: =COUNTIF(E30:P30,"UNPAID") -> 0 | T30: =D30*S30 -> 0
A31: =ROW()-6 -> 25 | B31: ='All Names'!B32 -> Student 25 | C31: ='All Names'!C32 -> 5th | D31: ='All Names'!E32 -> 500 | E31: UNPAID | F31: UNPAID | G31: UNPAID | H31: UNPAID | I31: UNPAID | J31: UNPAID | K31: UNPAID | L31: UNPAID | M31: UNPAID | N31: UNPAID | O31: UNPAID | Q31: =COUNTIF(E31:P31,"PAID") -> 0 | R31: =D31*Q31 -> 0 | S31: =COUNTIF(E31:P31,"UNPAID") -> 11 | T31: =D31*S31 -> 5500
A32: =ROW()-6 -> 26 | B32: ='All Names'!B33 -> Student 26 | C32: ='All Names'!C33 -> Jr.kg/Sr.kg | D32: ='All Names'!E33 -> 0 | E32: PAID | F32: PAID | G32: PAID | H32: PAID | I32: PAID | J32: PAID | K32: PAID | L32: PAID | M32: PAID | N32: PAID | O32: PAID | Q32: =COUNTIF(E32:P32,"PAID") -> 11 | R32: =D32*Q32 -> 0 | S32: =COUNTIF(E32:P32,"UNPAID") -> 0 | T32: =D32*S32 -> 0
A33: =ROW()-6 -> 27 | B33: ='All Names'!B34 -> Student 27 | C33: ='All Names'!C34 -> 3rd | D33: ='All Names'!E34 -> 300 | E33: PAID | F33: PAID | Q33: =COUNTIF(E33:P33,"PAID") -> 2 | R33: =D33*Q33 -> 600 | S33: =COUNTIF(E33:P33,"UNPAID") -> 0 | T33: =D33*S33 -> 0
A34: =ROW()-6 -> 28 | B34: ='All Names'!B35 -> Student 28 | C34: ='All Names'!C35 -> 4th | D34: ='All Names'!E35 -> 350 | E34: NOT CAME | F34: PAID | Q34: =COUNTIF(E34:P34,"PAID") -> 1 | R34: =D34*Q34 -> 350 | S34: =COUNTIF(E34:P34,"UNPAID") -> 0 | T34: =D34*S34 -> 0
A35: =ROW()-6 -> 29 | B35: ='All Names'!B36 -> Student 29 | C35: ='All Names'!C36 -> Jr.kg/Sr.kg | D35: ='All Names'!E36 -> 200 | E35: NOT CAME | F35: PAID | Q35: =COUNTIF(E35:P35,"PAID") -> 1 | R35: =D35*Q35 -> 200 | S35: =COUNTIF(E35:P35,"UNPAID") -> 0 | T35: =D35*S35 -> 0
A36: =ROW()-6 -> 30 | B36: ='All Names'!B37 -> Student 30 | C36: ='All Names'!C37 -> 0th | D36: ='All Names'!E37 -> 200 | E36: PAID | F36: LEFT | G36: LEFT | H36: LEFT | I36: LEFT | J36: LEFT | K36: LEFT | L36: LEFT | M36: LEFT | N36: LEFT | O36: LEFT | Q36: =COUNTIF(E36:P36,"PAID") -> 1 | R36: =D36*Q36 -> 200 | S36: =COUNTIF(E36:P36,"UNPAID") -> 0 | T36: =D36*S36 -> 0
A37: =ROW()-6 -> 31 | B37: ='All Names'!B38 -> Student 31 | C37: ='All Names'!C38 -> 3rd | D37: ='All Names'!E38 -> 300 | E37: PAID | F37: PAID | Q37: =COUNTIF(E37:P37,"PAID") -> 2 | R37: =D37*Q37 -> 600 | S37: =COUNTIF(E37:P37,"UNPAID") -> 0 | T37: =D37*S37 -> 0
A38: =ROW()-6 -> 32 | B38: ='All Names'!B39 -> Student 32 | C38: ='All Names'!C39 -> Jr.kg/Sr.kg | D38: ='All Names'!E39 -> 150 | E38: PAID | F38: PAID | Q38: =COUNTIF(E38:P38,"PAID") -> 2 | R38: =D38*Q38 -> 300 | S38: =COUNTIF(E38:P38,"UNPAID") -> 0 | T38: =D38*S38 -> 0
A39: =ROW()-6 -> 33 | B39: ='All Names'!B40 -> Student 33 | C39: ='All Names'!C40 -> 0th | D39: ='All Names'!E40 -> 200 | E39: UNPAID | F39: NOT CAME | G39: NOT CAME | Q39: =COUNTIF(E39:P39,"PAID") -> 0 | R39: =D39*Q39 -> 0 | S39: =COUNTIF(E39:P39,"UNPAID") -> 1 | T39: =D39*S39 -> 200
A40: =ROW()-6 -> 34 | B40: ='All Names'!B41 -> Student 34 | C40: ='All Names'!C41 -> 0th | D40: ='All Names'!E41 -> 150 | E40: UNPAID | F40: UNPAID | G40: UNPAID | H40: UNPAID | I40: UNPAID | J40: UNPAID | K40: UNPAID | L40: UNPAID | M40: UNPAID | N40: UNPAID | O40: UNPAID | Q40: =COUNTIF(E40:P40,"PAID") -> 0 | R40: =D40*Q40 -> 0 | S40: =COUNTIF(E40:P40,"UNPAID") -> 11 | T40: =D40*S40 -> 1650
A41: =ROW()-6 -> 35 | B41: ='All Names'!B42 -> Student 35 | C41: ='All Names'!C42 -> 9th | D41: ='All Names'!E42 -> 900 | E41: PAID | F41: PAID | Q41: =COUNTIF(E41:P41,"PAID") -> 2 | R41: =D41*Q41 -> 1800 | S41: =COUNTIF(E41:P41,"UNPAID") -> 0 | T41: =D41*S41 -> 0
A42: =ROW()-6 -> 36 | B42: ='All Names'!B43 -> Student 36 | C42: ='All Names'!C43 -> 3rd | D42: ='All Names'!E43 -> 250 | E42: NOT CAME | F42: UNPAID | Q42: =COUNTIF(E42:P42,"PAID") -> 0 | R42: =D42*Q42 -> 0 | S42: =COUNTIF(E42:P42,"UNPAID") -> 1 | T42: =D42*S42 -> 250
A43: =ROW()-6 -> 37 | B43: ='All Names'!B44 -> Student 37 | C43: ='All Names'!C44 -> 1st | D43: ='All Names'!E44 -> 200 | E43: NOT CAME | F43: UNPAID | Q43: =COUNTIF(E43:P43,"PAID") -> 0 | R43: =D43*Q43 -> 0 | S43: =COUNTIF(E43:P43,"UNPAID") -> 1 | T43: =D43*S43 -> 200
A44: =ROW()-6 -> 38 | B44: ='All Names'!B45 -> Student 38 | C44: ='All Names'!C45 -> 3rd | D44: ='All Names'!E45 -> 250 | E44: NOT CAME | F44: PAID | Q44: =COUNTIF(E44:P44,"PAID") -> 1 | R44: =D44*Q44 -> 250 | S44: =COUNTIF(E44:P44,"UNPAID") -> 0 | T44: =D44*S44 -> 0
...

Sheet Montly Fees Received
A1: MONTLY FEES RECEIVED : 2026 - 2027
A5: FEES RECEIVED IN JUNE MONTH
A7: SR.NO. | B7: NAME | C7: FEES | D7: DUE DATE | E7: PAID DATE | F7: STATUS | G7: PAYMENT MODE
A8: =ROW()-7 -> 1 | B8: ='Regular Fees '!B7 -> Student 1 | C8: ='Regular Fees '!D7 -> 200 | D8: 46204 | E8: - | F8: ='Regular Fees '!E7 -> PAID | G8: CASH | I8: JUNE FEES CALCULATION
A9: =ROW()-7 -> 2 | B9: ='Regular Fees '!B20 -> Student 14 | C9: ='Regular Fees '!D20 -> 400 | D9: 46204 | E9: - | F9: ='Regular Fees '!E20 -> PAID | G9: CASH
A10: =ROW()-7 -> 3 | B10: ='Regular Fees '!B21 -> Student 15 | C10: ='Regular Fees '!D21 -> 300 | D10: 46204 | E10: - | F10: ='Regular Fees '!E21 -> PAID | G10: CASH | I10: TOTAL | K10: =SUM(C8:C21) -> 4200
A11: =ROW()-7 -> 4 | B11: ='Regular Fees '!B25 -> Student 19 | C11: ='Regular Fees '!D25 -> 250 | D11: 46204 | E11: - | F11: ='Regular Fees '!E25 -> PAID | G11: UPI
A12: =ROW()-7 -> 5 | B12: ='Regular Fees '!B26 -> Student 20 | C12: ='Regular Fees '!D26 -> 300 | D12: 46204 | E12: - | F12: ='Regular Fees '!E26 -> PAID | G12: CASH | I12: PAID FEES | K12: =SUMIF(Table3[STATUS],"PAID",Table3[FEES]) -> 4000
A13: =ROW()-7 -> 6 | B13: ='Regular Fees '!B28 -> Student 22 | C13: ='Regular Fees '!D28 -> 250 | D13: 46204 | E13: - | F13: ='Regular Fees '!E28 -> PAID | G13: CASH
A14: =ROW()-7 -> 7 | B14: ='Regular Fees '!B30 -> Student 24 | C14: ='Regular Fees '!D30 -> 200 | D14: 46204 | E14: - | F14: ='Regular Fees '!E30 -> PAID | G14: CASH | I14: UNPAID FEES | K14: =SUMIF(F8:F21,"UNPAID",C8:C21) -> 200
A15: =ROW()-7 -> 8 | B15: ='Regular Fees '!B36 -> Student 30 | C15: ='Regular Fees '!D36 -> 200 | D15: 46204 | E15: - | F15: ='Regular Fees '!E36 -> PAID | G15: UPI
A16: =ROW()-7 -> 9 | B16: ='Regular Fees '!B29 -> Student 23 | C16: ='Regular Fees '!D29 -> 250 | D16: 46213 | E16: - | F16: ='Regular Fees '!E29 -> PAID | G16: CASH
A17: =ROW()-7 -> 10 | B17: ='Regular Fees '!B33 -> Student 27 | C17: ='Regular Fees '!D33 -> 300 | D17: 46213 | E17: - | F17: ='Regular Fees '!E33 -> PAID | G17: CASH
A18: =ROW()-7 -> 11 | B18: ='Regular Fees '!B37 -> Student 31 | C18: ='Regular Fees '!D37 -> 300 | D18: 46213 | E18: - | F18: ='Regular Fees '!E37 -> PAID | G18: CASH
A19: =ROW()-7 -> 12 | B19: ='Regular Fees '!B38 -> Student 32 | C19: ='Regular Fees '!D38 -> 150 | D19: 46213 | E19: - | F19: ='Regular Fees '!E38 -> PAID | G19: CASH
A20: =ROW()-7 -> 13 | B20: ='Regular Fees '!B39 -> Student 33 | C20: ='Regular Fees '!D39 -> 200 | D20: 46213 | E20: - | F20: ='Regular Fees '!E39 -> UNPAID | G20: -
A21: =ROW()-7 -> 14 | B21: ='Regular Fees '!B41 -> Student 35 | C21: ='Regular Fees '!D41 -> 900 | D21: 46213 | E21: - | F21: ='Regular Fees '!E41 -> PAID | G21: UPI
A22: =ROW()-7 -> 15
A26: FEES RECEIVED IN JULY MONTH
A28: SR.NO. | B28: NAME | C28: FEES | D28: DUE DATE | E28: PAID DATE | F28: STATUS | G28: PAYMENT MODE
A29: =ROW()-28 -> 1 | B29: ='Regular Fees '!B7 -> Student 1 | C29: ='Regular Fees '!D7 -> 200 | D29: 46235 | E29: 46237 | F29: ='Regular Fees '!F7 -> PAID | G29: CASH | I29: JULY FEES CALCULATION
A30: =ROW()-28 -> 2 | B30: ='Regular Fees '!B17 -> Student 11 | C30: ='Regular Fees '!D17 -> 800 | D30: 46235 | E30: 46249 | F30: ='Regular Fees '!F17 -> PAID | G30: UPI
A31: =ROW()-28 -> 3 | B31: ='Regular Fees '!B18 -> Student 12 | C31: ='Regular Fees '!D18 -> 500 | D31: 46235 | E31: 46249 | F31: ='Regular Fees '!F18 -> PAID | G31: UPI | I31: TOTAL | K31: =SUM(Table36[FEES]) -> 12950
A32: =ROW()-28 -> 4 | B32: ='Regular Fees '!B20 -> Student 14 | C32: ='Regular Fees '!D20 -> 400 | D32: 46235 | E32: 46238 | F32: ='Regular Fees '!F20 -> PAID | G32: CASH
A33: =ROW()-28 -> 5 | B33: ='Regular Fees '!B21 -> Student 15 | C33: ='Regular Fees '!D21 -> 300 | D33: 46235 | E33: 46238 | F33: ='Regular Fees '!F21 -> PAID | G33: CASH | I33: PAID FEES | K33: =SUMIF(Table36[STATUS],"PAID",Table36[FEES]) -> 12250
A34: =ROW()-28 -> 6 | B34: ='Regular Fees '!B23 -> Student 17 | C34: ='Regular Fees '!D23 -> 300 | D34: 46235 | E34: 46241 | F34: ='Regular Fees '!F23 -> PAID | G34: CASH
A35: =ROW()-28 -> 7 | B35: ='Regular Fees '!B24 -> Student 18 | C35: ='Regular Fees '!D24 -> 350 | D35: 46235 | E35: 46245 | F35: ='Regular Fees '!F24 -> PAID | G35: UPI | I35: UNPAID FEES | K35: =SUMIF(Table36[STATUS],"UNPAID",Table36[FEES]) -> 700
A36: =ROW()-28 -> 8 | B36: ='Regular Fees '!B25 -> Student 19 | C36: ='Regular Fees '!D25 -> 250 | D36: 46235 | E36: 46238 | F36: ='Regular Fees '!F25 -> PAID | G36: CASH
A37: =ROW()-28 -> 9 | B37: ='Regular Fees '!B26 -> Student 20 | C37: ='Regular Fees '!D26 -> 300 | D37: 46235 | E37: 46183 | F37: ='Regular Fees '!F26 -> PAID | G37: CASH
A38: =ROW()-28 -> 10 | B38: ='Regular Fees '!B28 -> Student 22 | C38: ='Regular Fees '!D28 -> 250 | D38: 46235 | F38: ='Regular Fees '!F28 -> UNPAID | G38: -
A39: =ROW()-28 -> 11 | B39: ='Regular Fees '!B29 -> Student 23 | C39: ='Regular Fees '!D29 -> 250 | D39: 46244 | E39: 46245 | F39: ='Regular Fees '!F29 -> PAID | G39: CASH
A40: =ROW()-28 -> 12 | B40: ='Regular Fees '!B30 -> Student 24 | C40: ='Regular Fees '!D30 -> 200 | D40: 46235 | E40: 46239 | F40: ='Regular Fees '!F30 -> PAID | G40: CASH
A41: =ROW()-28 -> 13 | B41: ='Regular Fees '!B33 -> Student 27 | C41: ='Regular Fees '!D33 -> 300 | D41: 46244 | E41: 46245 | F41: ='Regular Fees '!F33 -> PAID | G41: CASH
A42: =ROW()-28 -> 14 | B42: ='Regular Fees '!B37 -> Student 31 | C42: ='Regular Fees '!D37 -> 300 | D42: 46244 | E42: 46245 | F42: ='Regular Fees '!F37 -> PAID | G42: CASH
A43: =ROW()-28 -> 15 | B43: ='Regular Fees '!B38 -> Student 32 | C43: ='Regular Fees '!D38 -> 150 | D43: 46244 | E43: 46245 | F43: ='Regular Fees '!F38 -> PAID | G43: CASH
A44: =ROW()-28 -> 16 | B44: ='Regular Fees '!B41 -> Student 35 | C44: ='Regular Fees '!D41 -> 900 | D44: 46244 | E44: 46245 | F44: ='Regular Fees '!F41 -> PAID | G44: UPI
A45: =ROW()-28 -> 17 | B45: ='Regular Fees '!B42 -> Student 36 | C45: ='Regular Fees '!D42 -> 250 | D45: 46235 | F45: ='Regular Fees '!F42 -> UNPAID | G45: -
A46: =ROW()-28 -> 18 | B46: ='Regular Fees '!B43 -> Student 37 | C46: ='Regular Fees '!D43 -> 200 | D46: 46235 | F46: ='Regular Fees '!F43 -> UNPAID | G46: -
A47: =ROW()-28 -> 19 | B47: ='Regular Fees '!B44 -> Student 38 | C47: ='Regular Fees '!D44 -> 250 | D47: 46235 | E47: 46239 | F47: ='Regular Fees '!F44 -> PAID | G47: UPI
A48: =ROW()-28 -> 20 | B48: ='Regular Fees '!B45 -> Student 39 | C48: ='Regular Fees '!D45 -> 200 | D48: 46235 | E48: 46239 | F48: ='Regular Fees '!F45 -> PAID | G48: UPI
...

Sheet Yearly Fees
A1: STUDENTS NAME GIVING YEARLY FEES : 2026-27
B5: GROUP 1 | G5: FINAL YEARLY FEES AMOUNTS GROUP WISE
B6: SR.NO. | C6: NAME | D6: FEES AMOUNT | G6: GROUP NO. | H6: TOTAL FEES | I6: TOTAL MONTHS | J6: AMOUNT | K6: DISCOUNT | L6: FINAL AMOUNT | M6: STATUS | N6: PAYMENT MODE
B7: 1 | C7: ="Student "&(ROW()-7) -> Student 0 | D7: ='All Names'!E13 -> 900 | G7: 1 | H7: =D12 -> 2550 | I7: 11 | J7: =H7*I7 -> 28050 | K7: 50 | L7: =J7-K7 -> 28000 | M7: UNPAID | N7: -
B8: 2 | C8: ="Student "&(ROW()-7) -> Student 1 | D8: ='All Names'!E12 -> 800 | G8: 2 | H8: =D19 -> 500 | I8: 11 | J8: =H8*I8 -> 5500 | K8: 0 | L8: =J8-K8 -> 5500 | M8: UNPAID | N8: -
B9: 3 | C9: ="Student "&(ROW()-7) -> Student 2 | D9: ='All Names'!E14 -> 600 | G9: 3 | H9: =D25 -> 1200 | I9: 10 | J9: =H9*I9 -> 12000 | K9: 0 | L9: =J9-K9 -> 12000 | M9: UNPAID | N9: -
B10: 4 | C10: ="Student "&(ROW()-7) -> Student 3 | D10: ='All Names'!E15 -> 250 | G10: 4 | H10: =D33 -> 800 | I10: 11 | J10: =H10*I10 -> 8800 | K10: 0 | L10: =J10-K10 -> 8800 | M10: UNPAID | N10: -
B11: 5 | C11: ="Student "&(ROW()-7) -> Student 4 | D11: 0 | G11: 5 | H11: =D40 -> 350 | I11: 11 | J11: =H11*I11 -> 3850 | K11: 150 | L11: =J11-K11 -> 3700 | M11: UNPAID | N11: -
B12: TOTAL = | D12: =SUM(D7:D11) -> 2550 | G12: 6 | H12: =D47 -> 500 | I12: 10 | J12: =H12*I12 -> 5000 | K12: 0 | L12: =J12-K12 -> 5000 | M12: UNPAID | N12: -
G13: TOTAL = | H13: =SUM(H7:H12) -> 5900 | J13: =SUM(J7:J12) -> 63200 | K13: =SUM(K7:K12) -> 200 | L13: =SUM(L7:L12) -> 63000
B15: GROUP 2
B16: SR.NO. | C16: NAME | D16: FEES AMOUNT
B17: 1 | C17: ="Student "&(ROW()-7) -> Student 10 | D17: ='All Names'!E32 -> 500
B18: 2 | C18: ="Student "&(ROW()-7) -> Student 11 | D18: ='All Names'!E33 -> 0
B19: TOTAL = | D19: =SUM(D17:D18) -> 500
B22: GROUP 3
B23: SR.NO. | C23: NAME | D23: FEES AMOUNT
B24: 1 | C24: ="Student "&(ROW()-7) -> Student 17 | D24: ='All Names'!E23 -> 1200
B25: TOTAL = | D25: =SUM(D24) -> 1200
B28: GROUP 4
B29: SR.NO. | C29: NAME | D29: FEES AMOUNT
B30: 1 | C30: ="Student "&(ROW()-7) -> Student 23 | D30: ='All Names'!E9 -> 400
B31: 2 | C31: ="Student "&(ROW()-7) -> Student 24 | D31: ='All Names'!E10 -> 400
B32: 3 | C32: ="Student "&(ROW()-7) -> Student 25 | D32: ='All Names'!E11 -> 0
B33: TOTAL = | D33: =SUM(D30:D32) -> 800
B36: GROUP 5
B37: SR.NO. | C37: NAME | D37: FEES AMOUNT
B38: 1 | C38: ="Student "&(ROW()-7) -> Student 31 | D38: ='All Names'!E20 -> 200
B39: 2 | C39: ="Student "&(ROW()-7) -> Student 32 | D39: ='All Names'!E41 -> 150
B40: TOTAL = | D40: =SUM(D38:D39) -> 350
B43: GROUP 6
B44: SR.NO. | C44: NAME | D44: FEES AMOUNT
B45: 1 | C45: ="Student "&(ROW()-7) -> Student 38 | D45: ='All Names'!E49 -> 300
B46: 2 | C46: ="Student "&(ROW()-7) -> Student 39 | D46: ='All Names'!E50 -> 200
B47: TOTAL = | D47: =SUM(D45:D46) -> 500

Sheet Maths Test
A1: MATHS TEST RECORD : 2026 - 2027
A5: TEST NO :- 01
A7: SR. NO. | B7: NAME | C7: STD | D7: TOTAL MARKS | E7: MARKS OBT. | F7: PERCENTAGE
A8: =ROW()-7 -> 1 | B8: ZEEDAN | C8: 9th | D8: 15 | E8: 9 | F8: =IFERROR(Table7[[#This Row],[MARKS OBT.]]/Table7[[#This Row],[TOTAL MARKS ]],"") -> 0.6
A9: =ROW()-7 -> 2 | B9: BILAL | C9: 6th | D9: 15 | E9: 12 | F9: =IFERROR(Table7[[#This Row],[MARKS OBT.]]/Table7[[#This Row],[TOTAL MARKS ]],"") -> 0.8
A10: =ROW()-7 -> 3 | B10: IQRA | C10: 8th | D10: 15 | E10: 14 | F10: =IFERROR(Table7[[#This Row],[MARKS OBT.]]/Table7[[#This Row],[TOTAL MARKS ]],"") -> 0.93333333
A11: =ROW()-7 -> 4 | B11: NAYRA | C11: 5th | D11: 15 | E11: 14 | F11: =IFERROR(Table7[[#This Row],[MARKS OBT.]]/Table7[[#This Row],[TOTAL MARKS ]],"") -> 0.93333333
A12: =ROW()-7 -> 5 | B12: JIYA | C12: 8th | D12: 15 | E12: 10 | F12: =IFERROR(Table7[[#This Row],[MARKS OBT.]]/Table7[[#This Row],[TOTAL MARKS ]],"") -> 0.66666667
A13: =ROW()-7 -> 6 | B13: ANKITA | C13: 8th | D13: 15 | E13: 6 | F13: =IFERROR(Table7[[#This Row],[MARKS OBT.]]/Table7[[#This Row],[TOTAL MARKS ]],"") -> 0.4
A14: =ROW()-7 -> 7 | B14: SHAALU | C14: 9th | D14: 15 | E14: 10 | F14: =IFERROR(Table7[[#This Row],[MARKS OBT.]]/Table7[[#This Row],[TOTAL MARKS ]],"") -> 0.66666667
A15: =ROW()-7 -> 8 | B15: SARTHAK | C15: 5th | D15: 15 | E15: 8 | F15: =IFERROR(Table7[[#This Row],[MARKS OBT.]]/Table7[[#This Row],[TOTAL MARKS ]],"") -> 0.53333333
A16: =ROW()-7 -> 9 | B16: KARISHMA | C16: 5th | D16: 15 | E16: 7 | F16: =IFERROR(Table7[[#This Row],[MARKS OBT.]]/Table7[[#This Row],[TOTAL MARKS ]],"") -> 0.46666667
A17: =ROW()-7 -> 10 | B17: SHALINI | C17: 5th | D17: 15 | E17: 8 | F17: =IFERROR(Table7[[#This Row],[MARKS OBT.]]/Table7[[#This Row],[TOTAL MARKS ]],"") -> 0.53333333
A18: =ROW()-7 -> 11 | B18: NIKHIL | C18: 5th | D18: 15 | E18: 9 | F18: =IFERROR(Table7[[#This Row],[MARKS OBT.]]/Table7[[#This Row],[TOTAL MARKS ]],"") -> 0.6
A19: =ROW()-7 -> 12 | B19: SATYAM | C19: 4th | D19: 15 | E19: 12 | F19: =IFERROR(Table7[[#This Row],[MARKS OBT.]]/Table7[[#This Row],[TOTAL MARKS ]],"") -> 0.8
A20: =ROW()-7 -> 13 | F20: =IFERROR(Table7[[#This Row],[MARKS OBT.]]/Table7[[#This Row],[TOTAL MARKS ]],"")
A21: =ROW()-7 -> 14 | F21: =IFERROR(Table7[[#This Row],[MARKS OBT.]]/Table7[[#This Row],[TOTAL MARKS ]],"")
A22: =ROW()-7 -> 15 | F22: =IFERROR(Table7[[#This Row],[MARKS OBT.]]/Table7[[#This Row],[TOTAL MARKS ]],"")
A25: TEST NO :- 02
A27: SR. NO. | B27: NAME | C27: STD | D27: TOTAL MARKS | E27: MARKS OBT. | F27: PERCENTAGE
A28: =ROW()-27 -> 1 | B28: ZEEDAN | C28: 9th | D28: 15 | E28: 12 | F28: =IFERROR(Table78[[#This Row],[MARKS OBT.]]/Table78[[#This Row],[TOTAL MARKS ]],"") -> 0.8
A29: =ROW()-27 -> 2 | B29: BILAL | C29: 6th | D29: 15 | E29: 10 | F29: =IFERROR(Table78[[#This Row],[MARKS OBT.]]/Table78[[#This Row],[TOTAL MARKS ]],"") -> 0.66666667
A30: =ROW()-27 -> 3 | B30: IQRA | C30: 8th | D30: 15 | E30: 6 | F30: =IFERROR(Table78[[#This Row],[MARKS OBT.]]/Table78[[#This Row],[TOTAL MARKS ]],"") -> 0.4
A31: =ROW()-27 -> 4 | B31: NAYRA | C31: 5th | D31: 15 | E31: 12 | F31: =IFERROR(Table78[[#This Row],[MARKS OBT.]]/Table78[[#This Row],[TOTAL MARKS ]],"") -> 0.8
A32: =ROW()-27 -> 5 | B32: JIYA | C32: 8th | D32: 15 | E32: 8 | F32: =IFERROR(Table78[[#This Row],[MARKS OBT.]]/Table78[[#This Row],[TOTAL MARKS ]],"") -> 0.53333333
A33: =ROW()-27 -> 6 | B33: ANKITA | C33: 8th | D33: 15 | E33: 7 | F33: =IFERROR(Table78[[#This Row],[MARKS OBT.]]/Table78[[#This Row],[TOTAL MARKS ]],"") -> 0.46666667
A34: =ROW()-27 -> 7 | F34: =IFERROR(Table78[[#This Row],[MARKS OBT.]]/Table78[[#This Row],[TOTAL MARKS ]],"")
A35: =ROW()-27 -> 8 | F35: =IFERROR(Table78[[#This Row],[MARKS OBT.]]/Table78[[#This Row],[TOTAL MARKS ]],"")
A36: =ROW()-27 -> 9 | F36: =IFERROR(Table78[[#This Row],[MARKS OBT.]]/Table78[[#This Row],[TOTAL MARKS ]],"")
A37: =ROW()-27 -> 10 | F37: =IFERROR(Table78[[#This Row],[MARKS OBT.]]/Table78[[#This Row],[TOTAL MARKS ]],"")
A38: =ROW()-27 -> 11 | F38: =IFERROR(Table78[[#This Row],[MARKS OBT.]]/Table78[[#This Row],[TOTAL MARKS ]],"")
A39: =ROW()-27 -> 12 | F39: =IFERROR(Table78[[#This Row],[MARKS OBT.]]/Table78[[#This Row],[TOTAL MARKS ]],"")
A40: =ROW()-27 -> 13 | F40: =IFERROR(Table78[[#This Row],[MARKS OBT.]]/Table78[[#This Row],[TOTAL MARKS ]],"")
A41: =ROW()-27 -> 14 | F41: =IFERROR(Table78[[#This Row],[MARKS OBT.]]/Table78[[#This Row],[TOTAL MARKS ]],"")
A42: =ROW()-27 -> 15 | F42: =IFERROR(Table78[[#This Row],[MARKS OBT.]]/Table78[[#This Row],[TOTAL MARKS ]],"")
A45: TEST NO :- 03
A47: SR. NO. | B47: NAME | C47: STD | D47: TOTAL MARKS | E47: MARKS OBT. | F47: PERCENTAGE
A48: =ROW()-47 -> 1 | B48: ZEEDAN | C48: 9th | D48: 15 | E48: 3 | F48: =IFERROR(Table789[[#This Row],[MARKS OBT.]]/Table789[[#This Row],[TOTAL MARKS ]],"") -> 0.2
A49: =ROW()-47 -> 2 | B49: BILAL | C49: 6th | D49: 15 | E49: 11 | F49: =IFERROR(Table789[[#This Row],[MARKS OBT.]]/Table789[[#This Row],[TOTAL MARKS ]],"") -> 0.73333333
A50: =ROW()-47 -> 3 | B50: IQRA | C50: 8th | D50: 15 | E50: 11 | F50: =IFERROR(Table789[[#This Row],[MARKS OBT.]]/Table789[[#This Row],[TOTAL MARKS ]],"") -> 0.73333333
...

Sheet Maths Test Summary 
A1: MATHS TEST SUMMARY : 2026 - 2027
A5: SR.NO. | B5: NAME | C5: TEST 01 | D5: TEST 02 | E5: TEST 03 | F5: TEST 04 | G5: TEST 05 | H5: TEST 06 | I5: TEST 07 | J5: TEST 08 | K5: TEST 09 | L5: TEST 10 | M5: OVERALL %
A6: =ROW()-5 -> 1 | B6: ='Maths Test'!B8 -> ZEEDAN | C6: ='Maths Test'!F8 -> 0.6 | D6: ='Maths Test'!F28 -> 0.8 | E6: ='Maths Test'!F48 -> 0.2 | F6: ='Maths Test'!F68 -> 0.8 | M6: =IFERROR(AVERAGE(Table9[[#This Row],[TEST 01]:[TEST 10]]),"") -> 0.6
A7: =ROW()-5 -> 2 | B7: ='Maths Test'!B9 -> BILAL | C7: ='Maths Test'!F9 -> 0.8 | D7: ='Maths Test'!F29 -> 0.66666667 | E7: ='Maths Test'!F49 -> 0.73333333 | F7: ='Maths Test'!F69 -> 0.6 | M7: =IFERROR(AVERAGE(Table9[[#This Row],[TEST 01]:[TEST 10]]),"") -> 0.7
A8: =ROW()-5 -> 3 | B8: ='Maths Test'!B10 -> IQRA | C8: ='Maths Test'!F10 -> 0.93333333 | D8: ='Maths Test'!F30 -> 0.4 | E8: ='Maths Test'!F50 -> 0.73333333 | F8: ='Maths Test'!F70 -> 0.4 | M8: =IFERROR(AVERAGE(Table9[[#This Row],[TEST 01]:[TEST 10]]),"") -> 0.61666667
A9: =ROW()-5 -> 4 | B9: ='Maths Test'!B11 -> NAYRA | C9: ='Maths Test'!F11 -> 0.93333333 | D9: ='Maths Test'!F31 -> 0.8 | E9: ='Maths Test'!F51 -> 0.66666667 | F9: ='Maths Test'!F71 -> 0.86666667 | M9: =IFERROR(AVERAGE(Table9[[#This Row],[TEST 01]:[TEST 10]]),"") -> 0.81666667
A10: =ROW()-5 -> 5 | B10: ='Maths Test'!B12 -> JIYA | C10: ='Maths Test'!F12 -> 0.66666667 | D10: ='Maths Test'!F32 -> 0.53333333 | E10: ='Maths Test'!F52 -> 0.066666667 | M10: =IFERROR(AVERAGE(Table9[[#This Row],[TEST 01]:[TEST 10]]),"") -> 0.42222222
A11: =ROW()-5 -> 6 | B11: ='Maths Test'!B13 -> ANKITA | C11: ='Maths Test'!F13 -> 0.4 | D11: ='Maths Test'!F33 -> 0.46666667 | M11: =IFERROR(AVERAGE(Table9[[#This Row],[TEST 01]:[TEST 10]]),"") -> 0.43333333
A12: =ROW()-5 -> 7 | B12: ='Maths Test'!B14 -> SHAALU | C12: ='Maths Test'!F14 -> 0.66666667 | M12: =IFERROR(AVERAGE(Table9[[#This Row],[TEST 01]:[TEST 10]]),"") -> 0.66666667
A13: =ROW()-5 -> 8 | B13: ='Maths Test'!B15 -> SARTHAK | C13: ='Maths Test'!F15 -> 0.53333333 | M13: =IFERROR(AVERAGE(Table9[[#This Row],[TEST 01]:[TEST 10]]),"") -> 0.53333333
A14: =ROW()-5 -> 9 | B14: ='Maths Test'!B16 -> KARISHMA | C14: ='Maths Test'!F16 -> 0.46666667 | M14: =IFERROR(AVERAGE(Table9[[#This Row],[TEST 01]:[TEST 10]]),"") -> 0.46666667
A15: =ROW()-5 -> 10 | B15: ='Maths Test'!B17 -> SHALINI | C15: ='Maths Test'!F17 -> 0.53333333 | M15: =IFERROR(AVERAGE(Table9[[#This Row],[TEST 01]:[TEST 10]]),"") -> 0.53333333
A16: =ROW()-5 -> 11 | B16: ='Maths Test'!B18 -> NIKHIL | C16: ='Maths Test'!F18 -> 0.6 | M16: =IFERROR(AVERAGE(Table9[[#This Row],[TEST 01]:[TEST 10]]),"") -> 0.6
A17: =ROW()-5 -> 12 | B17: ='Maths Test'!B19 -> SATYAM | C17: ='Maths Test'!F19 -> 0.8 | M17: =IFERROR(AVERAGE(Table9[[#This Row],[TEST 01]:[TEST 10]]),"") -> 0.8
A18: =ROW()-5 -> 13 | M18: =IFERROR(AVERAGE(Table9[[#This Row],[TEST 01]:[TEST 10]]),"")
A19: =ROW()-5 -> 14 | M19: =IFERROR(AVERAGE(Table9[[#This Row],[TEST 01]:[TEST 10]]),"")
A20: =ROW()-5 -> 15 | M20: =IFERROR(AVERAGE(Table9[[#This Row],[TEST 01]:[TEST 10]]),"")

Sheet 10th std syllabus
A1: 10TH STD ALL SUBJECT CHAPTER WISE TRACKER : 2026 - 2027
A7: ENGLISH | F7: HINDI | K7: MARATHI | P7: MATHS-1 | U7: SCI-1 | Z7: HISTORY & POLITICAL SCI
A9: CHP NO. | B9: CHP NAME | C9: Y/N | F9: CHP NO. | G9: CHP NAME | H9: Y/N | K9: CHP NO. | L9: CHP NAME | M9: Y/N | P9: CHP NO. | Q9: CHP NAME | R9: Y/N | U9: CHP NO. | V9: CHP NAME | W9: Y/N | Z9: CHP NO. | AA9: CHP NAME | AB9: Y/N
A10: 1.1 | B10: Where the Mind is Without Fear | C10: N | F10: 1 | G10: भारत महिमा | H10: Y | K10: 1 | L10: तू बुद्धी दे (प्रार्थना) | M10: Y | P10: 1 | Q10: Linear Equations in Two Variables | R10: Y | U10: 1 | V10: Gravitation | W10: Y | Z10: 1 | AA10: Historiography : Development in the West. | AB10: Y
A11: 1.2 | B11: The Thief’s Story | C11: N | F11: 2 | G11: लक्ष्मी | H11: Y | K11: 2(a) | L11: संतवाणी (अ) अंकिला मी दास तुझा-संत नामदेव | M11: Y | P11: 2 | Q11: Quadratic Equations | R11: Y | U11: 2 | V11: Periodic Classification of Element | W11: Y | Z11: 2 | AA11: Historiography : Indian Tradition | AB11: Y
A12: 1.3 | B12: On Wings of Courage | C12: N | F12: 3 | G12: वाह रे! दर्द | H12: Y | K12: 2(b) | L12: संतवाणी (आ) योगी सर्वकाळ सुखदाता-संत एकनाथ | M12: Y | P12: 3 | Q12: Arithmetic Progression | R12: Y | U12: 3 | V12: Chemical reactions and equations | W12: Y | Z12: 3 | AA12: Applied History | AB12: Y
A13: 1.4 | B13: All the World’s a Stage | C13: N | F13: 4 | G13: मन (एक पठन) | H13: Y | K13: 3 | L13: शाल | M13: Y | P13: 4 | Q13: Financial Planning | R13: N | U13: 4 | V13: Effects of electric current | W13: N | Z13: 4 | AA13: History of Indian Arts | AB13: N
A14: 1.5 | B14: Joan of Arc | C14: N | F14: 5 | G14: गोवा : जैसा मैंने देखा | H14: Y | K14: 4 | L14: उपास | M14: Y | P14: 5 | Q14: Probability | R14: N | U14: 5 | V14: Heat | W14: Y | Z14: 5 | AA14: Mass Media and History | AB14: Y
A15: 1.6 | B15: The Alchemy of Nature | C15: N | F15: 6 | G15: गिरधर नागर | H15: N | K15: * | L15: मोठे होत असलेल्या मुलांनो..(स्थूलवाचन) | M15: Y | P15: 6 | Q15: Statistics | R15: N | U15: 6 | V15: Refraction of light | W15: N | Z15: 6 | AA15: Entertainment and History | AB15: N
A16: 2.1 | B16: Animals | C16: N | F16: 7 | G16: खुला आकाश (एक पठन) | H16: N | K16: 5 | L16: दोन दिवस (कविता) | M16: N | U16: 7 | V16: Lenses | W16: N | Z16: 7 | AA16: Sports and History | AB16: N
A17: 2.2 | B17: Three Questions | C17: N | F17: 8 | G17: ग़ज़ल | H17: N | K17: 6 | L17: चुडीवाला | M17: N | U17: 8 | V17: Metallurgy | W17: N | Z17: 8 | AA17: Tourism and History. | AB17: N
A18: 2.3 | B18: Connecting the Dots | C18: N | F18: 9 | G18: गीत की हड्डी | H18: N | K18: 7 | L18: फूटप्रिन्टस | M18: N | U18: 9 | V18: Carbon compounds | W18: N | Z18: 9 | AA18: Heritage Management | AB18: N
A19: 2.4 | B19: The Pulley | C19: N | F19: 10 | G19: ठेस (एक पठन) | H19: N | K19: 8 | L19: ऊर्जाशक्तीचा जागर | M19: N | U19: 10 | V19: Space Missions | W19: N | Z19: 1 | AA19: Working of the Constitution | AB19: Y
A20: 2.5 | B20: Let’s March | C20: N | F20: 11 | G20: कूक का गान | H20: N | K20: * | L20: जाता अस्ताला (स्थूलवाचन) | M20: N | Z20: 2 | AA20: The Electoral Process | AB20: N
A21: 2.6 | B21: Science and Spirituality | C21: N | F21: 1 | G21: वर्षा जलद | H21: N | K21: 9 | L21: औक्षण (कविता) | M21: N | Z21: 3 | AA21: Political Parties. | AB21: N
A22: 3.1 | B22: Night of the Scorpion | C22: N | F22: 2 | G22: दो लघुकथाएँ (एक पठन) | H22: N | K22: 10 | L22: रंग साहित्याचे | M22: N | Z22: 4 | AA22: Social and Political Movements.. | AB22: N
A23: 3.2 | B23: The Night I Met Einstein | C23: N | F23: 3 | G23: श्रम साधना | H23: N | K23: 11 | L23: जंगल डायरी | M23: N | Z23: 5 | AA23: Challenges faced by Indian Democracy | AB23: N
A24: 3.3 | B24: Stephen Hawking | C24: N | F24: 4 | G24: छापा | H24: N | K24: 12 | L24: रंग मजेचे रंग उदयाचे (कविता) | M24: N
A25: 3.4 | B25: The Will to Win | C25: N | F25: 5 | G25: ईमानदारी की प्रतिमूर्ति | H25: N | K25: * | L25: जगणं कॅक्टसचं (स्थूलवाचन) | M25: N
A26: 3.5 | B26: Unbeatable Super Mom-Mary Kom | C26: N | F26: 6 | G26: हम इस धरती के सन्तान हैं (एक पठन) | H26: N | K26: 13 | L26: हिरवंगार झाडासारखं (कविता) | M26: N | P26: MATHS-2 | U26: SCI-2 | Z26: GEOGRAPHY
A27: 3.6 | B27: The Concert | C27: N | F27: 7 | G27: महिला आश्रम | H27: N | K27: 14 | L27: बीज पेरले गेले | M27: N
A28: 4.1 | B28: A Thing of Beauty is a Joy For Ever | C28: N | F28: 8 | G28: अपनी गंध नहीं बेचूँगा | H28: N | K28: 15 | L28: खरा नागरिक | M28: N | P28: CHP NO. | Q28: CHP NAME | R28: Y/N | U28: CHP NO. | V28: CHP NAME | W28: Y/N | Z28: CHP NO. | AA28: CHP NAME | AB28: Y/N
A29: 4.2 | B29: The Luncheon | C29: N | F29: 9 | G29: जब तक जिंदा हूँ, लिखता हूँ | H29: N | K29: 16 | L29: स्वप्न करू साकार (कविता) | M29: N | P29: 1 | Q29: Similarity | R29: Y | U29: 1 | V29: Heredity and Evolution | W29: Y | Z29: 1 | AA29: Field Visit | AB29: Y
A30: 4.3 | B30: World Heritage | C30: N | F30: 10 | G30: बूढ़ी काकी (एक पठन) | H30: N | K30: * | L30: व्युत्पत्ती कोश (स्थूलवाचन) | M30: N | P30: 2 | Q30: Pythagoras Theorem | R30: Y | U30: 2 | V30: Life Processes in Living Organisms Part -1 | W30: Y | Z30: 2 | AA30: Location and Extent | AB30: Y
A31: 4.4 | B31: The Height of the Ridiculous | C31: N | F31: 11 | G31: समता की ओर | H31: N | P31: 3 | Q31: Circle | R31: N | U31: 3 | V31: Life Processes in Living Organisms Part - 2 | W31: N | Z31: 3 | AA31: Physiography and Drainage | AB31: N
A32: 4.5 | B32: The Old Man and The Sea : Book Review | C32: N | P32: 4 | Q32: Geometric Construction | R32: N | U32: 4 | V32: Environmental management | W32: Y | Z32: 4 | AA32: Climate | AB32: Y
A33: 4.6 | B33: The Gift of the Magi | C33: N | P33: 5 | Q33: Co-Ordinate Geometry | R33: Y | U33: 5 | V33: Towards Green Energy | W33: Y | Z33: 5 | AA33: Natural Vegetation and Wildlife | AB33: Y
P34: 6 | Q34: Trigonometry | R34: N | U34: 6 | V34: Animal Classification | W34: N | Z34: 6 | AA34: Population | AB34: N
P35: 7 | Q35: Mensuration | R35: N | U35: 7 | V35: Introduction to Microbiology | W35: N | Z35: 7 | AA35: Human Settlements | AB35: N
U36: 8 | V36: Cell Biology and Biotechnology | W36: N | Z36: 8 | AA36: Economy and Occupations | AB36: N
F37: HINDI GRAMMAR | K37: MARATHI GRAMMAR | U37: 9 | V37: Social health | W37: N | Z37: 9 | AA37: Tourism, Transport and Communication | AB37: N
U38: 10 | V38: Disaster Management | W38: N
F39: SR.NO. | G39: TOPIC | H39: Y/N | K39: SR.NO. | L39: TOPIC | M39: Y/N
F40: 1 | G40: शब्द भेद (1m) | H40: Y | K40: 1 | L40: वाक्यांच े प्रकार (2 of 2) (2M) | M40: N
F41: 2 | G41: अव्यय (1 of 2) (1m) | H41: N | K41: 2 | L41: वाक्य रुपांतर (2 of 2) (2M) | M41: N
F42: 3 | G42: संध ि (1 of 2) (1m) | H42: N | K42: 3 | L42: वाक् प्रचार (2 of 3) (4M) | M42: N
F43: 4 | G43: सहायकक्रिय (1 of 2) (1m) | H43: N | K43: 4 | L43: समानार्थी (2 of 2) (1M) | M43: N
F44: 5 | G44: प्रेरणार्थक क्रिया (1 of 2) (1m) | H44: N | K44: 5 | L44: विरुद्धार्थी (2 of 2) (1M) | M44: N
F45: 6 | G45: मुहावरे (1 of 2) (1m) | H45: Y | K45: 6 | L45: वचन (2 of 2) (1M) | M45: N
F46: 7 | G46: कारक (1 of 2) (1m) | H46: Y | K46: 7 | L46: शब्दसमूहबदल (1 of 1) (1M) | M46: N
...

Sheet Time Table 
A1: EXAM TIME-TABLE : 2026 - 2027
A6: SR.NO. | B6: DATE | C6: DAY | D6: SUBJECT | E6: CHAPTERS | F6: MARKS | G6: TIME | I6: MARKS OBT. | J6: PERCENTAGE
A7: 1 | B7: 46218 | C7: WEDNESDAY | D7: GEOMETRY | E7: Similarity | F7: 40 | G7: 2 HOURS | I7: 30 | J7: =I7/F7 -> 0.75
E8: Pythagoras Theorem
A9: 2 | B9: 46221 | C9: SATURDAY | D9: SCI-1 | E9: ='10th std syllabus'!V10 -> Gravitation | F9: 40 | G9: 2 HOURS | I9: 27 | J9: =I9/F9 -> 0.675
E10: ='10th std syllabus'!V11 -> Periodic Classification of Element
E11: ='10th std syllabus'!V12 -> Chemical reactions and equations
A12: 3 | B12: 46223 | C12: MONDAY | D12: ALGEBRA | E12: Linear Equations in Two Variables | F12: 40 | G12: 2 HOURS | I12: 20.5 | J12: =I12/F12 -> 0.5125
E13: Quadratic Equations
A14: 4 | B14: 46225 | C14: WEDNESDAY | D14: GEOGRAPHY | E14: ='10th std syllabus'!AA29 -> Field Visit | F14: 22 | G14: 1.5 HOURS | I14: 15 | J14: =I14/F14 -> 0.68181818
E15: ='10th std syllabus'!AA30 -> Location and Extent
E16: ='10th std syllabus'!AA32 -> Climate
A17: 5 | B17: 46228 | C17: SATURDAY | D17: SCI-2 | E17: ='10th std syllabus'!V29 -> Heredity and Evolution | F17: 40 | G17: 2 HOURS | I17: 33 | J17: =I17/F17 -> 0.825
E18: ='10th std syllabus'!V30 -> Life Processes in Living Organisms Part -1
E19: ='10th std syllabus'!V32 -> Environmental management
A20: 6 | B20: 46230 | C20: MONDAY | D20: HISTORY | E20: Historiography : Development in the West. | F20: 30 | G20: 1.5 HOURS | I20: 29 | J20: =I20/F20 -> 0.96666667
E21: Historiography : Indian Tradition
A24: SR.NO. | B24: DATE | C24: DAY | D24: SUBJECT | E24: CHAPTERS | F24: MARKS | G24: TIME | I24: MARKS OBT. | J24: PERCENTAGE
A25: 1 | B25: 46244 | C25: MONDAY | D25: SCI-1 | E25: ='10th std syllabus'!V11 -> Periodic Classification of Element | F25: 20 | G25: 1 HOUR | I25: 18 | J25: =I25/F25 -> 0.9
E26: ='10th std syllabus'!V14 -> Heat
E27: -
A28: 2 | B28: 46246 | C28: WEDNESDAY | D28: SCI-2 | E28: ='10th std syllabus'!V33 -> Towards Green Energy | F28: 20 | G28: 1 HOUR | I28: 16 | J28: =I28/F28 -> 0.8
E29: ='10th std syllabus'!V32 -> Environmental management
E30: -
A31: 3 | B31: 46248 | C31: FRIDAY | D31: ALGEBRA | E31: ='10th std syllabus'!Q10 -> Linear Equations in Two Variables | F31: 40 | G31: 2 HOUR | I31: 28 | J31: =I31/F31 -> 0.7
E32: ='10th std syllabus'!Q11 -> Quadratic Equations
E33: ='10th std syllabus'!Q12 -> Arithmetic Progression
A34: 4 | B34: 46251 | C34: MONDAY | D34: GEOMETRY | E34: ='10th std syllabus'!Q29 -> Similarity | F34: 40 | G34: 2 HOUR | J34: =I34/F34 -> 0
E35: ='10th std syllabus'!Q30 -> Pythagoras Theorem
E36: ='10th std syllabus'!Q33 -> Co-Ordinate Geometry
A37: 5 | B37: 46253 | C37: WEDNESDAY | D37: HISTORY | E37: ='10th std syllabus'!AA12 -> Applied History | F37: 25 | G37: 1.15 HOUR | J37: =I37/F37 -> 0
E38: ='10th std syllabus'!AA14 -> Mass Media and History
E39: ='10th std syllabus'!AA19 -> Working of the Constitution
A40: 6 | B40: 46256 | C40: SATURDAY | D40: GEOGRAPHY | E40: ='10th std syllabus'!AA29 -> Field Visit | F40: 30 | G40: 1.30 HOUR | J40: =I40/F40 -> 0
E41: ='10th std syllabus'!AA33 -> Natural Vegetation and Wildlife
E42: ='10th std syllabus'!AA32 -> Climate

Sheet All_Pivot_Table
A3: ADMISSION DETAIL | B3: Column Labels
A4: Row Labels | B4: ACTIVE | C4: LEFT | D4: Grand Total
A5: 0th | B5: 8 | C5: 1 | D5: 9 | G5: FEES DETAIL
A6: 1st | B6: 7 | D6: 7 | G6: LEFT | H6: Grand Total
A7: 2nd | B7: 4 | C7: 1 | D7: 5 | F7: Sum of MONTHLY FEES | G7: 3050 | H7: 3050
A8: 3rd | B8: 9 | D8: 9
A9: 4th | B9: 11 | D9: 11
A10: 10th | B10: 1 | C10: 1 | D10: 2
A11: Grand Total | B11: 40 | C11: 3 | D11: 43
A25: Sum of FEES AMOUNT | B25: Column Labels
A26: Row Labels | B26: PAID | C26: UNPAID | D26: Grand Total
A27: 0th | B27: 200 | C27: 350 | D27: 550
A28: 10th | C28: 1200 | D28: 1200
A29: 1st | B29: 450 | C29: 1050 | D29: 1500
A30: 2nd | B30: 250 | C30: 550 | D30: 800
A31: 3rd | B31: 2050 | C31: 250 | D31: 2300
A32: 4th | B32: 3350 | C32: 400 | D32: 3750
A33: 5th | B33: 2500 | C33: 500 | D33: 3000
A34: 6th | C34: 600 | D34: 600
A35: 8th | B35: 1600 | C35: 800 | D35: 2400
A36: 9th | B36: 900 | C36: 900 | D36: 1800
A37: Jr.kg/Sr.kg | B37: 950 | D37: 950
A38: Grand Total | B38: 12250 | C38: 6600 | D38: 18850
